Workbook

Sheet TRABALHO DE LINHA DE BASE
B2: Nível da estrutura de tópicos | C2: Status | D2: Crítica | E2: Nome da Tarefa | F2: % LB Prevista | G2: % Real | H2: Duração real | I2: Duração restante | J2: Início LB | K2: Início Real | L2: Previsão de Início | M2: Término LB | N2: Término Real | O2: Previsão de Término | P2: Custo | Q2: 46160 | R2: =Q2+7 -> 46167 | S2: =R2+7 -> 46174 | T2: =S2+7 -> 46181 | U2: =T2+7 -> 46188 | V2: =U2+7 -> 46195 | W2: =V2+7 -> 46202 | X2: =W2+7 -> 46209 | Y2: =X2+7 -> 46216 | ... GD2: =GC2+7 -> 47343
B3: 0 | C3: No Prazo | D3: Sim | E3: UNIPAR_PROJETO_SPCI+PLATAFORMA | F3: 0.3414 | G3: 0.0824 | H3: 58,91 dias | I3: 59,09 dias | J3: Qua 20/05/26 09:00 | K3: Qua 20/05/26 09:00 | L3: Qua 20/05/26 09:00 | M3: Qua 21/10/26 16:00 | N3: ND | O3: Qui 05/11/26 16:00 | P3: 10028.87 | T3: 181.5 | U3: 201.8 | V3: 222.1 | W3: 242.4 | X3: 302.7 | Y3: 338.7 | Z3: 656.21 | AA3: 2150.74 | AB3: 3424.09 | AC3: 4529.92 | AD3: 5324.73 | AE3: 5806.22 | AF3: 6569.31 | AG3: 6970.3 | AH3: 7695.58 | AI3: 8116.14 | AJ3: 8616.87 | AK3: 9223.37 | AL3: 9793.87 | AM3: 10028.87 | AN3: 10028.87 | AO3: 10028.87
B4: 1 | C4: Atrasada | D4: Não | E4: MARCOS CONTRATUAIS | F4: 0 | G4: 0 | H4: 0 dias | I4: 103,14 dias | J4: Qua 20/05/26 09:00 | K4: Qua 20/05/26 09:00 | L4: Qua 20/05/26 09:00 | M4: Qua 30/09/26 09:52 | N4: ND | O4: Qui 15/10/26 09:52 | P4: 0 | Q4: 0 | AJ4: 0 | AK4: 0 | AL4: 0 | AM4: 0 | AN4: 0 | AO4: 0
B5: 2 | C5: Atrasada | D5: Não | E5: MARCOS CONTRATUAIS | F5: 0 | G5: 0 | H5: 0 dias | I5: 103,14 dias | J5: ND | K5: Qua 20/05/26 09:00 | L5: Qua 20/05/26 09:00 | M5: ND | N5: ND | O5: Qui 15/10/26 09:52 | P5: 0
B6: 3 | C6: Atrasada | D6: Não | E6: MARCOS CONTRATUAIS | F6: 0 | G6: 0 | H6: 0 dias | I6: 103,14 dias | J6: ND | K6: Qua 20/05/26 09:00 | L6: Qua 20/05/26 09:00 | M6: ND | N6: ND | O6: Qui 15/10/26 09:52 | P6: 0
B7: 4 | C7: Atrasada | D7: Não | E7: MARCOS CONTRATUAIS | F7: 0 | G7: 0 | H7: 0 dias | I7: 103,14 dias | J7: ND | K7: Qua 20/05/26 09:00 | L7: Qua 20/05/26 09:00 | M7: ND | N7: ND | O7: Qui 15/10/26 09:52 | P7: 0
B8: 1 | C8: No Prazo | D8: Não | E8: EXECUÇÃO - SPCI | F8: 0.4879 | G8: 0.1618 | H8: 54,51 dias | I8: 36,63 dias | J8: Seg 08/06/26 09:00 | K8: Seg 08/06/26 09:00 | L8: Seg 08/06/26 09:00 | M8: Qua 30/09/26 09:52 | N8: ND | O8: Qui 15/10/26 09:52 | P8: 5107.87 | T8: 181.5 | U8: 201.8 | V8: 222.1 | W8: 242.4 | X8: 302.7 | Y8: 338.7 | Z8: 656.21 | AA8: 1662.74 | AB8: 2492.09 | AC8: 3282.92 | AD8: 3824.73 | AE8: 4188.72 | AF8: 4467.81 | AG8: 4632.3 | AH8: 4965.58 | AI8: 5082.14 | AJ8: 5107.87 | AK8: 5107.87 | AL8: 5107.87 | AM8: 5107.87 | AN8: 5107.87 | AO8: 5107.87
B9: 2 | C9: No Prazo | D9: Não | E9: CWA (ÁREA 2 - SETOR X) | F9: 0.7234 | G9: 0.2216 | H9: 58,48 dias | I9: 22,82 dias | J9: Seg 08/06/26 09:00 | K9: Seg 08/06/26 09:00 | L9: Seg 08/06/26 09:00 | M9: Qua 16/09/26 10:46 | N9: ND | O9: Qua 30/09/26 10:46 | P9: 2695.9 | T9: 181.5 | U9: 183.9 | V9: 186.3 | W9: 188.7 | X9: 231.1 | Y9: 231.1 | Z9: 540.21 | AA9: 1350.9 | AB9: 1950.17 | AC9: 2319.25 | AD9: 2521.15 | AE9: 2557.04 | AF9: 2615.9 | AG9: 2657.06 | AH9: 2695.9 | AI9: 2695.9 | AJ9: 2695.9 | AK9: 2695.9 | AL9: 2695.9 | AM9: 2695.9 | AN9: 2695.9 | AO9: 2695.9
B10: 3 | C10: No Prazo | D10: Não | E10: CWP (ANDAIME) | F10: 0 | G10: 0 | H10: 0 dias | I10: 0 dias | J10: Sáb 25/07/26 16:00 | K10: ND | L10: Sex 07/08/26 16:00 | M10: Sáb 25/07/26 16:00 | N10: ND | O10: Sex 07/08/26 16:00 | P10: 0 | Z10: 0 | AA10: 0 | AB10: 0 | AC10: 0 | AD10: 0 | AE10: 0 | AF10: 0 | AG10: 0 | AH10: 0 | AI10: 0 | AJ10: 0 | AK10: 0 | AL10: 0 | AM10: 0 | AN10: 0 | AO10: 0
B11: 4 | C11: No Prazo | D11: Não | E11: IWP (MONTAGEM) | F11: 0 | G11: 0 | H11: 0 dias | I11: 0 dias | J11: Sáb 25/07/26 16:00 | K11: ND | L11: Sex 07/08/26 16:00 | M11: Sáb 25/07/26 16:00 | N11: ND | O11: Sex 07/08/26 16:00 | P11: 0 | Z11: 0 | AA11: 0 | AB11: 0 | AC11: 0 | AD11: 0 | AE11: 0 | AF11: 0 | AG11: 0 | AH11: 0 | AI11: 0 | AJ11: 0 | AK11: 0 | AL11: 0 | AM11: 0 | AN11: 0 | AO11: 0
B12: 3 | C12: No Prazo | D12: Não | E12: CWP (TUBULAÇÃO) | F12: 0.7153 | G12: 0.2556 | H12: 61,53 dias | I12: 18,1 dias | J12: Seg 08/06/26 09:00 | K12: Seg 08/06/26 09:00 | L12: Seg 08/06/26 09:00 | M12: Seg 14/09/26 13:46 | N12: ND | O12: Seg 28/09/26 13:46 | P12: 2337.3 | T12: 181.5 | U12: 183.9 | V12: 186.3 | W12: 188.7 | X12: 231.1 | Y12: 231.1 | Z12: 540.21 | AA12: 1211.9 | AB12: 1671.97 | AC12: 1980.65 | AD12: 2182.55 | AE12: 2218.43 | AF12: 2277.3 | AG12: 2318.46 | AH12: 2337.3 | AI12: 2337.3 | AJ12: 2337.3 | AK12: 2337.3 | AL12: 2337.3 | AM12: 2337.3 | AN12: 2337.3 | AO12: 2337.3
B13: 4 | C13: Concluída | D13: Não | E13: IWP (FABRICAÇÃO) | F13: 1 | G13: 1 | H13: 35 dias | I13: 0 dias | J13: Seg 08/06/26 09:00 | K13: Seg 08/06/26 09:00 | L13: Seg 08/06/26 09:00 | M13: Qua 29/07/26 11:00 | N13: Sáb 25/07/26 15:36 | O13: Sáb 25/07/26 15:36 | P13: 391.2 | T13: 181.5 | U13: 183.9 | V13: 186.3 | W13: 188.7 | X13: 191.1 | Y13: 191.1 | Z13: 334.1 | AA13: 391.2 | AB13: 391.2 | AC13: 391.2 | AD13: 391.2 | AE13: 391.2 | AF13: 391.2 | AG13: 391.2 | AH13: 391.2 | AI13: 391.2 | AJ13: 391.2 | AK13: 391.2 | AL13: 391.2 | AM13: 391.2 | AN13: 391.2 | AO13: 391.2
B14: 4 | C14: Concluída | D14: Não | E14: IWP (SUPORTE - FABRICAÇÃO) | F14: 1 | G14: 1 | H14: 10 dias | I14: 0 dias | J14: Seg 29/06/26 09:00 | K14: Seg 29/06/26 09:00 | L14: Seg 29/06/26 09:00 | M14: Sex 10/07/26 16:00 | N14: Sex 10/07/26 16:00 | O14: Sex 10/07/26 16:00 | P14: 40 | W14: 0 | X14: 40 | Y14: 40 | Z14: 40 | AA14: 40 | AB14: 40 | AC14: 40 | AD14: 40 | AE14: 40 | AF14: 40 | AG14: 40 | AH14: 40 | AI14: 40 | AJ14: 40 | AK14: 40 | AL14: 40 | AM14: 40 | AN14: 40 | AO14: 40
B15: 4 | C15: Tarefa futura | D15: Não | E15: IWP (SUPORTE - MONTAGEM) | F15: 1 | G15: 0 | H15: 0 dias | I15: 7,92 dias | J15: Seg 27/07/26 09:00 | K15: ND | L15: Seg 10/08/26 09:00 | M15: Qua 05/08/26 15:30 | N15: ND | O15: Qua 19/08/26 15:30 | P15: 95 | AA15: 60 | AB15: 95 | AC15: 95 | AD15: 95 | AE15: 95 | AF15: 95 | AG15: 95 | AH15: 95 | AI15: 95 | AJ15: 95 | AK15: 95 | AL15: 95 | AM15: 95 | AN15: 95 | AO15: 95
B16: 4 | C16: No Prazo | D16: Não | E16: IWP (MONTAGEM) | F16: 0.6525 | G16: 0.0954 | H16: 4,5 dias | I16: 38,77 dias | J16: Seg 20/07/26 09:00 | K16: Seg 20/07/26 09:00 | L16: Seg 20/07/26 09:00 | M16: Qui 03/09/26 10:37 | N16: ND | O16: Sex 18/09/26 10:37 | P16: 1742.1 | Z16: 166.11 | AA16: 720.7 | AB16: 1136.77 | AC16: 1445.45 | AD16: 1647.35 | AE16: 1683.24 | AF16: 1742.1 | AG16: 1742.1 | AH16: 1742.1 | AI16: 1742.1 | AJ16: 1742.1 | AK16: 1742.1 | AL16: 1742.1 | AM16: 1742.1 | AN16: 1742.1 | AO16: 1742.1
B17: 4 | C17: Tarefa futura | D17: Não | E17: IWP (CIVIL) | F17: 1 | G17: 0 | H17: 0 dias | I17: 1,5 dias | J17: Seg 03/08/26 15:00 | K17: ND | L17: Seg 10/08/26 09:00 | M17: Qua 05/08/26 11:00 | N17: ND | O17: Ter 11/08/26 12:00 | P17: 9 | AB17: 9 | AC17: 9 | AD17: 9 | AE17: 9 | AF17: 9 | AG17: 9 | AH17: 9 | AI17: 9 | AJ17: 9 | AK17: 9 | AL17: 9 | AM17: 9 | AN17: 9 | AO17: 9
B18: 4 | C18: Tarefa futura | D18: Não | E18: IWP (TIE-IN) | F18: 0 | G18: 0 | H18: 0 dias | I18: 1,67 dias | J18: Qui 10/09/26 15:46 | K18: ND | L18: Qui 24/09/26 15:46 | M18: Seg 14/09/26 13:46 | N18: ND | O18: Seg 28/09/26 13:46 | P18: 60 | AG18: 41.16 | AH18: 60 | AI18: 60 | AJ18: 60 | AK18: 60 | AL18: 60 | AM18: 60 | AN18: 60 | AO18: 60
B19: 3 | C19: Tarefa futura | D19: Não | E19: CWP (ELÉTRICA) | F19: 0.8216 | G19: 0 | H19: 0 dias | I19: 12,62 dias | J19: Seg 27/07/26 09:00 | K19: ND | L19: Seg 10/08/26 09:00 | M19: Qua 12/08/26 13:42 | N19: ND | O19: Qua 26/08/26 13:42 | P19: 338.6 | AA19: 139 | AB19: 278.2 | AC19: 338.6 | AD19: 338.6 | AE19: 338.6 | AF19: 338.6 | AG19: 338.6 | AH19: 338.6 | AI19: 338.6 | AJ19: 338.6 | AK19: 338.6 | AL19: 338.6 | AM19: 338.6 | AN19: 338.6 | AO19: 338.6
B20: 4 | C20: Tarefa futura | D20: Não | E20: IWP (INFRAESTRUTURA) FABRICAR DE SUPORTE | F20: 1 | G20: 0 | H20: 0 dias | I20: 1,67 dias | J20: Seg 27/07/26 09:00 | K20: ND | L20: Seg 10/08/26 09:00 | M20: Ter 28/07/26 14:00 | N20: ND | O20: Ter 11/08/26 14:00 | P20: 20 | AA20: 20 | AB20: 20 | AC20: 20 | AD20: 20 | AE20: 20 | AF20: 20 | AG20: 20 | AH20: 20 | AI20: 20 | AJ20: 20 | AK20: 20 | AL20: 20 | AM20: 20 | AN20: 20 | AO20: 20
B21: 4 | C21: Tarefa futura | D21: Não | E21: IWP (INFRAESTRUTURA) MONTAGEM DE SUPORTE | F21: 1 | G21: 0 | H21: 0 dias | I21: 1,67 dias | J21: Ter 28/07/26 14:00 | K21: ND | L21: Ter 11/08/26 14:00 | M21: Qui 30/07/26 11:00 | N21: ND | O21: Qui 13/08/26 11:00 | P21: 20 | AA21: 20 | AB21: 20 | AC21: 20 | AD21: 20 | AE21: 20 | AF21: 20 | AG21: 20 | AH21: 20 | AI21: 20 | AJ21: 20 | AK21: 20 | AL21: 20 | AM21: 20 | AN21: 20 | AO21: 20
B22: 4 | C22: Tarefa futura | D22: Não | E22: IWP (INFRAESTRUTURA) MONTAGEM DE ELETROCALHA | F22: 1 | G22: 0 | H22: 0 dias | I22: 7,95 dias | J22: Qua 29/07/26 09:00 | K22: ND | L22: Qua 12/08/26 09:00 | M22: Sex 07/08/26 15:42 | N22: ND | O22: Sex 21/08/26 15:42 | P22: 201.6 | AA22: 83 | AB22: 201.6 | AC22: 201.6 | AD22: 201.6 | AE22: 201.6 | AF22: 201.6 | AG22: 201.6 | AH22: 201.6 | AI22: 201.6 | AJ22: 201.6 | AK22: 201.6 | AL22: 201.6 | AM22: 201.6 | AN22: 201.6 | AO22: 201.6
B23: 4 | C23: Tarefa futura | D23: Não | E23: IWP (CABEAMENTO) | F23: 0.4486 | G23: 0 | H23: 0 dias | I23: 5,68 dias | J23: Seg 03/08/26 13:36 | K23: ND | L23: Seg 17/08/26 13:36 | M23: Ter 11/08/26 10:42 | N23: ND | O23: Ter 25/08/26 10:42 | P23: 37 | AB23: 16.6 | AC23: 37 | AD23: 37 | AE23: 37 | AF23: 37 | AG23: 37 | AH23: 37 | AI23: 37 | AJ23: 37 | AK23: 37 | AL23: 37 | AM23: 37 | AN23: 37 | AO23: 37
B24: 4 | C24: Tarefa futura | D24: Não | E24: IWP (INSTALAÇÃO DE MALHA) | F24: 0.3333 | G24: 0 | H24: 0 dias | I24: 10,62 dias | J24: Qua 29/07/26 09:00 | K24: ND | L24: Qua 12/08/26 09:00 | M24: Qua 12/08/26 13:42 | N24: ND | O24: Qua 26/08/26 13:42 | P24: 48 | AA24: 16 | AB24: 16 | AC24: 48 | AD24: 48 | AE24: 48 | AF24: 48 | AG24: 48 | AH24: 48 | AI24: 48 | AJ24: 48 | AK24: 48 | AL24: 48 | AM24: 48 | AN24: 48 | AO24: 48
B25: 4 | C25: Tarefa futura | D25: Não | E25: IWP (TESTE) | F25: 0.3333 | G25: 0 | H25: 0 dias | I25: 5,18 dias | J25: Ter 04/08/26 10:36 | K25: ND | L25: Ter 18/08/26 10:36 | M25: Ter 11/08/26 11:42 | N25: ND | O25: Ter 25/08/26 11:42 | P25: 6 | AB25: 2 | AC25: 6 | AD25: 6 | AE25: 6 | AF25: 6 | AG25: 6 | AH25: 6 | AI25: 6 | AJ25: 6 | AK25: 6 | AL25: 6 | AM25: 6 | AN25: 6 | AO25: 6
B26: 4 | C26: Tarefa futura | D26: Não | E26: IWP (LIGAÇÃO) | F26: 0.3333 | G26: 0 | H26: 0 dias | I26: 6,18 dias | J26: Ter 04/08/26 11:36 | K26: ND | L26: Ter 18/08/26 11:36 | M26: Qua 12/08/26 13:42 | N26: ND | O26: Qua 26/08/26 13:42 | P26: 6 | AB26: 2 | AC26: 6 | AD26: 6 | AE26: 6 | AF26: 6 | AG26: 6 | AH26: 6 | AI26: 6 | AJ26: 6 | AK26: 6 | AL26: 6 | AM26: 6 | AN26: 6 | AO26: 6
B27: 3 | C27: Tarefa futura | D27: Não | E27: CWP (TESTE HIDROSTÁTICO) | F27: 0 | G27: 0 | H27: 0 dias | I27: 1,67 dias | J27: Seg 14/09/26 13:46 | K27: ND | L27: Seg 28/09/26 13:46 | M27: Qua 16/09/26 10:46 | N27: ND | O27: Qua 30/09/26 10:46 | P27: 20 | AH27: 20 | AI27: 20 | AJ27: 20 | AK27: 20 | AL27: 20 | AM27: 20 | AN27: 20 | AO27: 20
B28: 4 | C28: Tarefa futura | D28: Não | E28: IWP (TESDE HIDROSTÁTICO) | F28: 0 | G28: 0 | H28: 0 dias | I28: 1,67 dias | J28: Seg 14/09/26 13:46 | K28: ND | L28: Seg 28/09/26 13:46 | M28: Qua 16/09/26 10:46 | N28: ND | O28: Qua 30/09/26 10:46 | P28: 20 | AH28: 20 | AI28: 20 | AJ28: 20 | AK28: 20 | AL28: 20 | AM28: 20 | AN28: 20 | AO28: 20
B29: 3 | C29: Tarefa futura | D29: Não | E29: CWP (ANDAIME) | F29: 0 | G29: 0 | H29: 0 dias | I29: 0 dias | J29: Qua 16/09/26 10:46 | K29: ND | L29: Qua 30/09/26 10:46 | M29: Qua 16/09/26 10:46 | N29: ND | O29: Qua 30/09/26 10:46 | P29: 0 | AH29: 0 | AI29: 0 | AJ29: 0 | AK29: 0 | AL29: 0 | AM29: 0 | AN29: 0 | AO29: 0
B30: 4 | C30: Tarefa futura | D30: Não | E30: IWP (DESMONTAGEM) | F30: 0 | G30: 0 | H30: 0 dias | I30: 0 dias | J30: Qua 16/09/26 10:46 | K30: ND | L30: Qua 30/09/26 10:46 | M30: Qua 16/09/26 10:46 | N30: ND | O30: Qua 30/09/26 10:46 | P30: 0 | AH30: 0 | AI30: 0 | AJ30: 0 | AK30: 0 | AL30: 0 | AM30: 0 | AN30: 0 | AO30: 0
B31: 3 | C31: Tarefa futura | D31: Não | E31: CONCLUSÃO DA EXECUÇÃO DA ÁREA | F31: 0 | G31: 0 | H31: 0 dias | I31: 0 dias | J31: Qua 16/09/26 10:46 | K31: ND | L31: Qua 30/09/26 10:46 | M31: Qua 16/09/26 10:46 | N31: ND | O31: Qua 30/09/26 10:46 | P31: 0 | AH31: 0 | AI31: 0 | AJ31: 0 | AK31: 0 | AL31: 0 | AM31: 0 | AN31: 0 | AO31: 0
B32: 2 | C32: No Prazo | D32: Não | E32: CWA (ÁREA 3 - SETOR P/T) | F32: 0.3118 | G32: 0.1896 | H32: 48,27 dias | I32: 29,69 dias | J32: Seg 15/06/26 09:00 | K32: Seg 15/06/26 09:00 | L32: Seg 15/06/26 09:00 | M32: Qui 17/09/26 15:46 | N32: ND | O32: Qui 01/10/26 15:46 | P32: 838.6 | U32: 10.4 | V32: 20.8 | W32: 31.2 | X32: 41.6 | Y32: 77.6 | Z32: 86 | AA32: 152.2 | AB32: 261.49 | AC32: 528.03 | AD32: 721.6 | AE32: 778.6 | AF32: 778.6 | AG32: 778.6 | AH32: 838.6 | AI32: 838.6 | AJ32: 838.6 | AK32: 838.6 | AL32: 838.6 | AM32: 838.6 | AN32: 838.6 | AO32: 838.6
B33: 3 | C33: Tarefa futura | D33: Não | E33: CWP (ANDAIME) | F33: 0 | G33: 0 | H33: 0 dias | I33: 0 dias | J33: Qui 03/09/26 10:37 | K33: ND | L33: Sex 18/09/26 10:37 | M33: Qui 03/09/26 10:37 | N33: ND | O33: Sex 18/09/26 10:37 | P33: 0 | AF33: 0 | AG33: 0 | AH33: 0 | AI33: 0 | AJ33: 0 | AK33: 0 | AL33: 0 | AM33: 0 | AN33: 0 | AO33: 0
B34: 4 | C34: Tarefa futura | D34: Não | E34: IWP (MONTAGEM) | F34: 0 | G34: 0 | H34: 0 dias | I34: 0 dias | J34: Qui 03/09/26 10:37 | K34: ND | L34: Sex 18/09/26 10:37 | M34: Qui 03/09/26 10:37 | N34: ND | O34: Sex 18/09/26 10:37 | P34: 0 | AF34: 0 | AG34: 0 | AH34: 0 | AI34: 0 | AJ34: 0 | AK34: 0 | AL34: 0 | AM34: 0 | AN34: 0 | AO34: 0
B35: 3 | C35: No Prazo | D35: Não | E35: CWP (TUBULAÇÃO) | F35: 0.3512 | G35: 0.2135 | H35: 50,17 dias | I35: 26,13 dias | J35: Seg 15/06/26 09:00 | K35: Seg 15/06/26 09:00 | L35: Seg 15/06/26 09:00 | M35: Qua 16/09/26 10:46 | N35: ND | O35: Qua 30/09/26 10:46 | P35: 744.6 | U35: 10.4 | V35: 20.8 | W35: 31.2 | X35: 41.6 | Y35: 77.6 | Z35: 86 | AA35: 152.2 | AB35: 261.49 | AC35: 499.43 | AD35: 647.6 | AE35: 704.6 | AF35: 704.6 | AG35: 704.6 | AH35: 744.6 | AI35: 744.6 | AJ35: 744.6 | AK35: 744.6 | AL35: 744.6 | AM35: 744.6 | AN35: 744.6 | AO35: 744.6
B36: 4 | C36: No Prazo | D36: Não | E36: IWP (FABRICAÇÃO) | F36: 1 | G36: 0.6761 | H36: 39,1 dias | I36: 3,4 dias | J36: Seg 15/06/26 09:00 | K36: Seg 15/06/26 09:00 | L36: Seg 15/06/26 09:00 | M36: Qua 29/07/26 12:00 | N36: ND | O36: Qua 12/08/26 12:00 | P36: 127.2 | U36: 10.4 | V36: 20.8 | W36: 31.2 | X36: 41.6 | Y36: 77.6 | Z36: 86 | AA36: 127.2 | AB36: 127.2 | AC36: 127.2 | AD36: 127.2 | AE36: 127.2 | AF36: 127.2 | AG36: 127.2 | AH36: 127.2 | AI36: 127.2 | AJ36: 127.2 | AK36: 127.2 | AL36: 127.2 | AM36: 127.2 | AN36: 127.2 | AO36: 127.2
B37: 4 | C37: Concluída | D37: Não | E37: IWP (SUPORTE - FABRICAÇÃO) | F37: 1 | G37: 1 | H37: 4 dias | I37: 0 dias | J37: Seg 27/07/26 09:00 | K37: Ter 04/08/26 09:00 | L37: Ter 04/08/26 09:00 | M37: Sex 31/07/26 10:00 | N37: Sex 07/08/26 16:00 | O37: Sex 07/08/26 16:00 | P37: 25 | AA37: 25 | AB37: 25 | AC37: 25 | AD37: 25 | AE37: 25 | AF37: 25 | AG37: 25 | AH37: 25 | AI37: 25 | AJ37: 25 | AK37: 25 | AL37: 25 | AM37: 25 | AN37: 25 | AO37: 25
B38: 4 | C38: Tarefa futura | D38: Não | E38: IWP (SUPORTE - MONTAGEM) | F38: 0.5208 | G38: 1 | H38: 0 dias | I38: 4 dias | J38: Qua 05/08/26 15:30 | K38: ND | L38: Qua 19/08/26 15:30 | M38: Ter 11/08/26 15:30 | N38: ND | O38: Ter 25/08/26 15:30 | P38: 48 | AB38: 25 | AC38: 48 | AD38: 48 | AE38: 48 | AF38: 48 | AG38: 48 | AH38: 48 | AI38: 48 | AJ38: 48 | AK38: 48 | AL38: 48 | AM38: 48 | AN38: 48 | AO38: 48
B39: 4 | C39: Tarefa futura | D39: Não | E39: IWP (MONTAGEM) | F39: 0.1571 | G39: 0 | H39: 0 dias | I39: 17,03 dias | J39: Ter 04/08/26 09:48 | K39: ND | L39: Ter 18/08/26 09:48 | M39: Qui 27/08/26 10:00 | N39: ND | O39: Sex 11/09/26 10:00 | P39: 498.4 | AB39: 78.29 | AC39: 293.23 | AD39: 441.4 | AE39: 498.4 | AF39: 498.4 | AG39: 498.4 | AH39: 498.4 | AI39: 498.4 | AJ39: 498.4 | AK39: 498.4 | AL39: 498.4 | AM39: 498.4 | AN39: 498.4 | AO39: 498.4
B40: 4 | C40: Tarefa futura | D40: Não | E40: IWP (CIVIL) | F40: 1 | G40: 0 | H40: 0 dias | I40: 1 dia | J40: Qua 05/08/26 11:00 | K40: ND | L40: Ter 11/08/26 13:00 | M40: Qui 06/08/26 11:00 | N40: ND | O40: Qua 12/08/26 12:00 | P40: 6 | AB40: 6 | AC40: 6 | AD40: 6 | AE40: 6 | AF40: 6 | AG40: 6 | AH40: 6 | AI40: 6 | AJ40: 6 | AK40: 6 | AL40: 6 | AM40: 6 | AN40: 6 | AO40: 6
B41: 4 | C41: Tarefa futura | D41: Não | E41: IWP (TIE-IN) | F41: 0 | G41: 0 | H41: 0 dias | I41: 1,67 dias | J41: Seg 14/09/26 13:46 | K41: ND | L41: Seg 28/09/26 13:46 | M41: Qua 16/09/26 10:46 | N41: ND | O41: Qua 30/09/26 10:46 | P41: 40 | AH41: 40 | AI41: 40 | AJ41: 40 | AK41: 40 | AL41: 40 | AM41: 40 | AN41: 40 | AO41: 40
...

Sheet TRABALHO TENDÊNCIA
B2: Nível da estrutura de tópicos | C2: Status | D2: Crítica | E2: Nome da Tarefa | F2: % LB Prevista | G2: % Real | H2: Duração real | I2: Duração restante | J2: Início LB | K2: Início Real | L2: Previsão de Início | M2: Término LB | N2: Término Real | O2: Previsão de Término | P2: Custo | Q2: ='TRABALHO DE LINHA DE BASE'!Q2 -> 46160 | R2: ='TRABALHO DE LINHA DE BASE'!R2 -> 46167 | S2: ='TRABALHO DE LINHA DE BASE'!S2 -> 46174 | T2: ='TRABALHO DE LINHA DE BASE'!T2 -> 46181 | U2: ='TRABALHO DE LINHA DE BASE'!U2 -> 46188 | V2: ='TRABALHO DE LINHA DE BASE'!V2 -> 46195 | W2: ='TRABALHO DE LINHA DE BASE'!W2 -> 46202 | X2: ='TRABALHO DE LINHA DE BASE'!X2 -> 46209 | ... AS2: ='TRABALHO DE LINHA DE BASE'!AS2 -> 46356
B3: 0 | C3: No Prazo | D3: Sim | E3: UNIPAR_PROJETO_SPCI+PLATAFORMA | F3: 0.3414 | G3: 0.0824 | H3: 58,91 dias | I3: 59,09 dias | J3: Qua 20/05/26 09:00 | K3: Qua 20/05/26 09:00 | L3: Qua 20/05/26 09:00 | M3: Qua 21/10/26 16:00 | N3: ND | O3: Qui 05/11/26 16:00 | P3: 10028.87 | T3: 185.46 | U3: 214.62 | V3: 243.77 | W3: 272.93 | X3: 342.09 | Y3: 386.94 | Z3: 713.31 | AA3: 713.31 | AB3: 778.31 | AC3: 2191.74 | AD3: 3459.09 | AE3: 4567.92 | AF3: 5359.73 | AG3: 5694.33 | AH3: 6421.56 | AI3: 6970.3 | AJ3: 7695.58 | AK3: 8116.14 | AL3: 8548.87 | AM3: 9171.87 | AN3: 9793.87 | AO3: 10028.87
B4: 1 | C4: Atrasada | D4: Não | E4: MARCOS CONTRATUAIS | F4: 0 | G4: 0 | H4: 0 dias | I4: 103,14 dias | J4: Qua 20/05/26 09:00 | K4: Qua 20/05/26 09:00 | L4: Qua 20/05/26 09:00 | M4: Qua 30/09/26 09:52 | N4: ND | O4: Qui 15/10/26 09:52 | P4: 0
B5: 2 | C5: Atrasada | D5: Não | E5: MARCOS CONTRATUAIS | F5: 0 | G5: 0 | H5: 0 dias | I5: 103,14 dias | J5: ND | K5: Qua 20/05/26 09:00 | L5: Qua 20/05/26 09:00 | M5: ND | N5: ND | O5: Qui 15/10/26 09:52 | P5: 0
B6: 3 | C6: Atrasada | D6: Não | E6: MARCOS CONTRATUAIS | F6: 0 | G6: 0 | H6: 0 dias | I6: 103,14 dias | J6: ND | K6: Qua 20/05/26 09:00 | L6: Qua 20/05/26 09:00 | M6: ND | N6: ND | O6: Qui 15/10/26 09:52 | P6: 0
B7: 4 | C7: Atrasada | D7: Não | E7: MARCOS CONTRATUAIS | F7: 0 | G7: 0 | H7: 0 dias | I7: 103,14 dias | J7: ND | K7: Qua 20/05/26 09:00 | L7: Qua 20/05/26 09:00 | M7: ND | N7: ND | O7: Qui 15/10/26 09:52 | P7: 0
B8: 1 | C8: No Prazo | D8: Não | E8: EXECUÇÃO - SPCI | F8: 0.4879 | G8: 0.1618 | H8: 54,51 dias | I8: 36,63 dias | J8: Seg 08/06/26 09:00 | K8: Seg 08/06/26 09:00 | L8: Seg 08/06/26 09:00 | M8: Qua 30/09/26 09:52 | N8: ND | O8: Qui 15/10/26 09:52 | P8: 5107.87 | T8: 185.46 | U8: 214.62 | V8: 243.77 | W8: 272.93 | X8: 342.09 | Y8: 386.94 | Z8: 713.31 | AA8: 713.31 | AB8: 778.31 | AC8: 1703.74 | AD8: 2527.09 | AE8: 3320.92 | AF8: 3859.73 | AG8: 4120.33 | AH8: 4426.56 | AI8: 4632.3 | AJ8: 4965.58 | AK8: 5082.14 | AL8: 5107.87 | AM8: 5107.87 | AN8: 5107.87 | AO8: 5107.87
B9: 2 | C9: No Prazo | D9: Não | E9: CWA (ÁREA 2 - SETOR X) | F9: 0.7234 | G9: 0.2216 | H9: 58,48 dias | I9: 22,82 dias | J9: Seg 08/06/26 09:00 | K9: Seg 08/06/26 09:00 | L9: Seg 08/06/26 09:00 | M9: Qua 16/09/26 10:46 | N9: ND | O9: Qua 30/09/26 10:46 | P9: 2695.9 | T9: 185.46 | U9: 196.72 | V9: 207.97 | W9: 219.23 | X9: 270.49 | Y9: 279.34 | Z9: 597.31 | AA9: 597.31 | AB9: 597.31 | AC9: 1359.9 | AD9: 1950.17 | AE9: 2319.25 | AF9: 2521.15 | AG9: 2540.35 | AH9: 2615.9 | AI9: 2657.06 | AJ9: 2695.9 | AK9: 2695.9 | AL9: 2695.9 | AM9: 2695.9 | AN9: 2695.9 | AO9: 2695.9
B10: 3 | C10: No Prazo | D10: Não | E10: CWP (ANDAIME) | F10: 0 | G10: 0 | H10: 0 dias | I10: 0 dias | J10: Sáb 25/07/26 16:00 | K10: ND | L10: Sex 07/08/26 16:00 | M10: Sáb 25/07/26 16:00 | N10: ND | O10: Sex 07/08/26 16:00 | P10: 0 | AB10: 0
B11: 4 | C11: No Prazo | D11: Não | E11: IWP (MONTAGEM) | F11: 0 | G11: 0 | H11: 0 dias | I11: 0 dias | J11: Sáb 25/07/26 16:00 | K11: ND | L11: Sex 07/08/26 16:00 | M11: Sáb 25/07/26 16:00 | N11: ND | O11: Sex 07/08/26 16:00 | P11: 0 | AB11: 0
B12: 3 | C12: No Prazo | D12: Não | E12: CWP (TUBULAÇÃO) | F12: 0.7153 | G12: 0.2556 | H12: 61,53 dias | I12: 18,1 dias | J12: Seg 08/06/26 09:00 | K12: Seg 08/06/26 09:00 | L12: Seg 08/06/26 09:00 | M12: Seg 14/09/26 13:46 | N12: ND | O12: Seg 28/09/26 13:46 | P12: 2337.3 | T12: 185.46 | U12: 196.72 | V12: 207.97 | W12: 219.23 | X12: 270.49 | Y12: 279.34 | Z12: 597.31 | AA12: 597.31 | AB12: 597.31 | AC12: 1220.9 | AD12: 1671.97 | AE12: 1980.65 | AF12: 2182.55 | AG12: 2201.75 | AH12: 2277.3 | AI12: 2318.46 | AJ12: 2337.3 | AK12: 2337.3 | AL12: 2337.3 | AM12: 2337.3 | AN12: 2337.3 | AO12: 2337.3
B13: 4 | C13: Concluída | D13: Não | E13: IWP (FABRICAÇÃO) | F13: 1 | G13: 1 | H13: 35 dias | I13: 0 dias | J13: Seg 08/06/26 09:00 | K13: Seg 08/06/26 09:00 | L13: Seg 08/06/26 09:00 | M13: Qua 29/07/26 11:00 | N13: Sáb 25/07/26 15:36 | O13: Sáb 25/07/26 15:36 | P13: 391.2 | T13: 185.46 | U13: 196.72 | V13: 207.97 | W13: 219.23 | X13: 230.49 | Y13: 239.34 | Z13: 391.2 | AA13: 391.2 | AB13: 391.2 | AC13: 391.2 | AD13: 391.2 | AE13: 391.2 | AF13: 391.2 | AG13: 391.2 | AH13: 391.2 | AI13: 391.2 | AJ13: 391.2 | AK13: 391.2 | AL13: 391.2 | AM13: 391.2 | AN13: 391.2 | AO13: 391.2
B14: 4 | C14: Concluída | D14: Não | E14: IWP (SUPORTE - FABRICAÇÃO) | F14: 1 | G14: 1 | H14: 10 dias | I14: 0 dias | J14: Seg 29/06/26 09:00 | K14: Seg 29/06/26 09:00 | L14: Seg 29/06/26 09:00 | M14: Sex 10/07/26 16:00 | N14: Sex 10/07/26 16:00 | O14: Sex 10/07/26 16:00 | P14: 40 | W14: 0 | X14: 40 | Y14: 40 | Z14: 40 | AA14: 40 | AB14: 40 | AC14: 40 | AD14: 40 | AE14: 40 | AF14: 40 | AG14: 40 | AH14: 40 | AI14: 40 | AJ14: 40 | AK14: 40 | AL14: 40 | AM14: 40 | AN14: 40 | AO14: 40
B15: 4 | C15: Tarefa futura | D15: Não | E15: IWP (SUPORTE - MONTAGEM) | F15: 1 | G15: 0 | H15: 0 dias | I15: 7,92 dias | J15: Seg 27/07/26 09:00 | K15: ND | L15: Seg 10/08/26 09:00 | M15: Qua 05/08/26 15:30 | N15: ND | O15: Qua 19/08/26 15:30 | P15: 95 | AC15: 60 | AD15: 95 | AE15: 95 | AF15: 95 | AG15: 95 | AH15: 95 | AI15: 95 | AJ15: 95 | AK15: 95 | AL15: 95 | AM15: 95 | AN15: 95 | AO15: 95
B16: 4 | C16: No Prazo | D16: Não | E16: IWP (MONTAGEM) | F16: 0.6525 | G16: 0.0954 | H16: 4,5 dias | I16: 38,77 dias | J16: Seg 20/07/26 09:00 | K16: Seg 20/07/26 09:00 | L16: Seg 20/07/26 09:00 | M16: Qui 03/09/26 10:37 | N16: ND | O16: Sex 18/09/26 10:37 | P16: 1742.1 | Z16: 166.11 | AA16: 166.11 | AB16: 166.11 | AC16: 720.7 | AD16: 1136.77 | AE16: 1445.45 | AF16: 1647.35 | AG16: 1666.55 | AH16: 1742.1 | AI16: 1742.1 | AJ16: 1742.1 | AK16: 1742.1 | AL16: 1742.1 | AM16: 1742.1 | AN16: 1742.1 | AO16: 1742.1
B17: 4 | C17: Tarefa futura | D17: Não | E17: IWP (CIVIL) | F17: 1 | G17: 0 | H17: 0 dias | I17: 1,5 dias | J17: Seg 03/08/26 15:00 | K17: ND | L17: Seg 10/08/26 09:00 | M17: Qua 05/08/26 11:00 | N17: ND | O17: Ter 11/08/26 12:00 | P17: 9 | AC17: 9 | AD17: 9 | AE17: 9 | AF17: 9 | AG17: 9 | AH17: 9 | AI17: 9 | AJ17: 9 | AK17: 9 | AL17: 9 | AM17: 9 | AN17: 9 | AO17: 9
B18: 4 | C18: Tarefa futura | D18: Não | E18: IWP (TIE-IN) | F18: 0 | G18: 0 | H18: 0 dias | I18: 1,67 dias | J18: Qui 10/09/26 15:46 | K18: ND | L18: Qui 24/09/26 15:46 | M18: Seg 14/09/26 13:46 | N18: ND | O18: Seg 28/09/26 13:46 | P18: 60 | AI18: 41.16 | AJ18: 60 | AK18: 60 | AL18: 60 | AM18: 60 | AN18: 60 | AO18: 60
B19: 3 | C19: Tarefa futura | D19: Não | E19: CWP (ELÉTRICA) | F19: 0.8216 | G19: 0 | H19: 0 dias | I19: 12,62 dias | J19: Seg 27/07/26 09:00 | K19: ND | L19: Seg 10/08/26 09:00 | M19: Qua 12/08/26 13:42 | N19: ND | O19: Qua 26/08/26 13:42 | P19: 338.6 | AC19: 139 | AD19: 278.2 | AE19: 338.6 | AF19: 338.6 | AG19: 338.6 | AH19: 338.6 | AI19: 338.6 | AJ19: 338.6 | AK19: 338.6 | AL19: 338.6 | AM19: 338.6 | AN19: 338.6 | AO19: 338.6
B20: 4 | C20: Tarefa futura | D20: Não | E20: IWP (INFRAESTRUTURA) FABRICAR DE SUPORTE | F20: 1 | G20: 0 | H20: 0 dias | I20: 1,67 dias | J20: Seg 27/07/26 09:00 | K20: ND | L20: Seg 10/08/26 09:00 | M20: Ter 28/07/26 14:00 | N20: ND | O20: Ter 11/08/26 14:00 | P20: 20 | AC20: 20 | AD20: 20 | AE20: 20 | AF20: 20 | AG20: 20 | AH20: 20 | AI20: 20 | AJ20: 20 | AK20: 20 | AL20: 20 | AM20: 20 | AN20: 20 | AO20: 20
B21: 4 | C21: Tarefa futura | D21: Não | E21: IWP (INFRAESTRUTURA) MONTAGEM DE SUPORTE | F21: 1 | G21: 0 | H21: 0 dias | I21: 1,67 dias | J21: Ter 28/07/26 14:00 | K21: ND | L21: Ter 11/08/26 14:00 | M21: Qui 30/07/26 11:00 | N21: ND | O21: Qui 13/08/26 11:00 | P21: 20 | AC21: 20 | AD21: 20 | AE21: 20 | AF21: 20 | AG21: 20 | AH21: 20 | AI21: 20 | AJ21: 20 | AK21: 20 | AL21: 20 | AM21: 20 | AN21: 20 | AO21: 20
B22: 4 | C22: Tarefa futura | D22: Não | E22: IWP (INFRAESTRUTURA) MONTAGEM DE ELETROCALHA | F22: 1 | G22: 0 | H22: 0 dias | I22: 7,95 dias | J22: Qua 29/07/26 09:00 | K22: ND | L22: Qua 12/08/26 09:00 | M22: Sex 07/08/26 15:42 | N22: ND | O22: Sex 21/08/26 15:42 | P22: 201.6 | AC22: 83 | AD22: 201.6 | AE22: 201.6 | AF22: 201.6 | AG22: 201.6 | AH22: 201.6 | AI22: 201.6 | AJ22: 201.6 | AK22: 201.6 | AL22: 201.6 | AM22: 201.6 | AN22: 201.6 | AO22: 201.6
B23: 4 | C23: Tarefa futura | D23: Não | E23: IWP (CABEAMENTO) | F23: 0.4486 | G23: 0 | H23: 0 dias | I23: 5,68 dias | J23: Seg 03/08/26 13:36 | K23: ND | L23: Seg 17/08/26 13:36 | M23: Ter 11/08/26 10:42 | N23: ND | O23: Ter 25/08/26 10:42 | P23: 37 | AD23: 16.6 | AE23: 37 | AF23: 37 | AG23: 37 | AH23: 37 | AI23: 37 | AJ23: 37 | AK23: 37 | AL23: 37 | AM23: 37 | AN23: 37 | AO23: 37
B24: 4 | C24: Tarefa futura | D24: Não | E24: IWP (INSTALAÇÃO DE MALHA) | F24: 0.3333 | G24: 0 | H24: 0 dias | I24: 10,62 dias | J24: Qua 29/07/26 09:00 | K24: ND | L24: Qua 12/08/26 09:00 | M24: Qua 12/08/26 13:42 | N24: ND | O24: Qua 26/08/26 13:42 | P24: 48 | AC24: 16 | AD24: 16 | AE24: 48 | AF24: 48 | AG24: 48 | AH24: 48 | AI24: 48 | AJ24: 48 | AK24: 48 | AL24: 48 | AM24: 48 | AN24: 48 | AO24: 48
B25: 4 | C25: Tarefa futura | D25: Não | E25: IWP (TESTE) | F25: 0.3333 | G25: 0 | H25: 0 dias | I25: 5,18 dias | J25: Ter 04/08/26 10:36 | K25: ND | L25: Ter 18/08/26 10:36 | M25: Ter 11/08/26 11:42 | N25: ND | O25: Ter 25/08/26 11:42 | P25: 6 | AD25: 2 | AE25: 6 | AF25: 6 | AG25: 6 | AH25: 6 | AI25: 6 | AJ25: 6 | AK25: 6 | AL25: 6 | AM25: 6 | AN25: 6 | AO25: 6
B26: 4 | C26: Tarefa futura | D26: Não | E26: IWP (LIGAÇÃO) | F26: 0.3333 | G26: 0 | H26: 0 dias | I26: 6,18 dias | J26: Ter 04/08/26 11:36 | K26: ND | L26: Ter 18/08/26 11:36 | M26: Qua 12/08/26 13:42 | N26: ND | O26: Qua 26/08/26 13:42 | P26: 6 | AD26: 2 | AE26: 6 | AF26: 6 | AG26: 6 | AH26: 6 | AI26: 6 | AJ26: 6 | AK26: 6 | AL26: 6 | AM26: 6 | AN26: 6 | AO26: 6
B27: 3 | C27: Tarefa futura | D27: Não | E27: CWP (TESTE HIDROSTÁTICO) | F27: 0 | G27: 0 | H27: 0 dias | I27: 1,67 dias | J27: Seg 14/09/26 13:46 | K27: ND | L27: Seg 28/09/26 13:46 | M27: Qua 16/09/26 10:46 | N27: ND | O27: Qua 30/09/26 10:46 | P27: 20 | AJ27: 20 | AK27: 20 | AL27: 20 | AM27: 20 | AN27: 20 | AO27: 20
B28: 4 | C28: Tarefa futura | D28: Não | E28: IWP (TESDE HIDROSTÁTICO) | F28: 0 | G28: 0 | H28: 0 dias | I28: 1,67 dias | J28: Seg 14/09/26 13:46 | K28: ND | L28: Seg 28/09/26 13:46 | M28: Qua 16/09/26 10:46 | N28: ND | O28: Qua 30/09/26 10:46 | P28: 20 | AJ28: 20 | AK28: 20 | AL28: 20 | AM28: 20 | AN28: 20 | AO28: 20
B29: 3 | C29: Tarefa futura | D29: Não | E29: CWP (ANDAIME) | F29: 0 | G29: 0 | H29: 0 dias | I29: 0 dias | J29: Qua 16/09/26 10:46 | K29: ND | L29: Qua 30/09/26 10:46 | M29: Qua 16/09/26 10:46 | N29: ND | O29: Qua 30/09/26 10:46 | P29: 0 | AJ29: 0
B30: 4 | C30: Tarefa futura | D30: Não | E30: IWP (DESMONTAGEM) | F30: 0 | G30: 0 | H30: 0 dias | I30: 0 dias | J30: Qua 16/09/26 10:46 | K30: ND | L30: Qua 30/09/26 10:46 | M30: Qua 16/09/26 10:46 | N30: ND | O30: Qua 30/09/26 10:46 | P30: 0 | AJ30: 0
B31: 3 | C31: Tarefa futura | D31: Não | E31: CONCLUSÃO DA EXECUÇÃO DA ÁREA | F31: 0 | G31: 0 | H31: 0 dias | I31: 0 dias | J31: Qua 16/09/26 10:46 | K31: ND | L31: Qua 30/09/26 10:46 | M31: Qua 16/09/26 10:46 | N31: ND | O31: Qua 30/09/26 10:46 | P31: 0
B32: 2 | C32: No Prazo | D32: Não | E32: CWA (ÁREA 3 - SETOR P/T) | F32: 0.3118 | G32: 0.1896 | H32: 48,27 dias | I32: 29,69 dias | J32: Seg 15/06/26 09:00 | K32: Seg 15/06/26 09:00 | L32: Seg 15/06/26 09:00 | M32: Qui 17/09/26 15:46 | N32: ND | O32: Qui 01/10/26 15:46 | P32: 838.6 | U32: 10.4 | V32: 20.8 | W32: 31.2 | X32: 41.6 | Y32: 77.6 | Z32: 86 | AA32: 86 | AB32: 111 | AC32: 158.2 | AD32: 261.49 | AE32: 528.03 | AF32: 721.6 | AG32: 778.6 | AH32: 778.6 | AI32: 778.6 | AJ32: 838.6 | AK32: 838.6 | AL32: 838.6 | AM32: 838.6 | AN32: 838.6 | AO32: 838.6
B33: 3 | C33: Tarefa futura | D33: Não | E33: CWP (ANDAIME) | F33: 0 | G33: 0 | H33: 0 dias | I33: 0 dias | J33: Qui 03/09/26 10:37 | K33: ND | L33: Sex 18/09/26 10:37 | M33: Qui 03/09/26 10:37 | N33: ND | O33: Sex 18/09/26 10:37 | P33: 0 | AH33: 0
B34: 4 | C34: Tarefa futura | D34: Não | E34: IWP (MONTAGEM) | F34: 0 | G34: 0 | H34: 0 dias | I34: 0 dias | J34: Qui 03/09/26 10:37 | K34: ND | L34: Sex 18/09/26 10:37 | M34: Qui 03/09/26 10:37 | N34: ND | O34: Sex 18/09/26 10:37 | P34: 0 | AH34: 0
B35: 3 | C35: No Prazo | D35: Não | E35: CWP (TUBULAÇÃO) | F35: 0.3512 | G35: 0.2135 | H35: 50,17 dias | I35: 26,13 dias | J35: Seg 15/06/26 09:00 | K35: Seg 15/06/26 09:00 | L35: Seg 15/06/26 09:00 | M35: Qua 16/09/26 10:46 | N35: ND | O35: Qua 30/09/26 10:46 | P35: 744.6 | U35: 10.4 | V35: 20.8 | W35: 31.2 | X35: 41.6 | Y35: 77.6 | Z35: 86 | AA35: 86 | AB35: 111 | AC35: 158.2 | AD35: 261.49 | AE35: 499.43 | AF35: 647.6 | AG35: 704.6 | AH35: 704.6 | AI35: 704.6 | AJ35: 744.6 | AK35: 744.6 | AL35: 744.6 | AM35: 744.6 | AN35: 744.6 | AO35: 744.6
B36: 4 | C36: No Prazo | D36: Não | E36: IWP (FABRICAÇÃO) | F36: 1 | G36: 0.6761 | H36: 39,1 dias | I36: 3,4 dias | J36: Seg 15/06/26 09:00 | K36: Seg 15/06/26 09:00 | L36: Seg 15/06/26 09:00 | M36: Qua 29/07/26 12:00 | N36: ND | O36: Qua 12/08/26 12:00 | P36: 127.2 | U36: 10.4 | V36: 20.8 | W36: 31.2 | X36: 41.6 | Y36: 77.6 | Z36: 86 | AA36: 86 | AB36: 86 | AC36: 127.2 | AD36: 127.2 | AE36: 127.2 | AF36: 127.2 | AG36: 127.2 | AH36: 127.2 | AI36: 127.2 | AJ36: 127.2 | AK36: 127.2 | AL36: 127.2 | AM36: 127.2 | AN36: 127.2 | AO36: 127.2
B37: 4 | C37: Concluída | D37: Não | E37: IWP (SUPORTE - FABRICAÇÃO) | F37: 1 | G37: 1 | H37: 4 dias | I37: 0 dias | J37: Seg 27/07/26 09:00 | K37: Ter 04/08/26 09:00 | L37: Ter 04/08/26 09:00 | M37: Sex 31/07/26 10:00 | N37: Sex 07/08/26 16:00 | O37: Sex 07/08/26 16:00 | P37: 25 | AB37: 25 | AC37: 25 | AD37: 25 | AE37: 25 | AF37: 25 | AG37: 25 | AH37: 25 | AI37: 25 | AJ37: 25 | AK37: 25 | AL37: 25 | AM37: 25 | AN37: 25 | AO37: 25
B38: 4 | C38: Tarefa futura | D38: Não | E38: IWP (SUPORTE - MONTAGEM) | F38: 0.5208 | G38: 1 | H38: 0 dias | I38: 4 dias | J38: Qua 05/08/26 15:30 | K38: ND | L38: Qua 19/08/26 15:30 | M38: Ter 11/08/26 15:30 | N38: ND | O38: Ter 25/08/26 15:30 | P38: 48 | AD38: 25 | AE38: 48 | AF38: 48 | AG38: 48 | AH38: 48 | AI38: 48 | AJ38: 48 | AK38: 48 | AL38: 48 | AM38: 48 | AN38: 48 | AO38: 48
B39: 4 | C39: Tarefa futura | D39: Não | E39: IWP (MONTAGEM) | F39: 0.1571 | G39: 0 | H39: 0 dias | I39: 17,03 dias | J39: Ter 04/08/26 09:48 | K39: ND | L39: Ter 18/08/26 09:48 | M39: Qui 27/08/26 10:00 | N39: ND | O39: Sex 11/09/26 10:00 | P39: 498.4 | AD39: 78.29 | AE39: 293.23 | AF39: 441.4 | AG39: 498.4 | AH39: 498.4 | AI39: 498.4 | AJ39: 498.4 | AK39: 498.4 | AL39: 498.4 | AM39: 498.4 | AN39: 498.4 | AO39: 498.4
B40: 4 | C40: Tarefa futura | D40: Não | E40: IWP (CIVIL) | F40: 1 | G40: 0 | H40: 0 dias | I40: 1 dia | J40: Qua 05/08/26 11:00 | K40: ND | L40: Ter 11/08/26 13:00 | M40: Qui 06/08/26 11:00 | N40: ND | O40: Qua 12/08/26 12:00 | P40: 6 | AC40: 6 | AD40: 6 | AE40: 6 | AF40: 6 | AG40: 6 | AH40: 6 | AI40: 6 | AJ40: 6 | AK40: 6 | AL40: 6 | AM40: 6 | AN40: 6 | AO40: 6
B41: 4 | C41: Tarefa futura | D41: Não | E41: IWP (TIE-IN) | F41: 0 | G41: 0 | H41: 0 dias | I41: 1,67 dias | J41: Seg 14/09/26 13:46 | K41: ND | L41: Seg 28/09/26 13:46 | M41: Qua 16/09/26 10:46 | N41: ND | O41: Qua 30/09/26 10:46 | P41: 40 | AJ41: 40 | AK41: 40 | AL41: 40 | AM41: 40 | AN41: 40 | AO41: 40
...

Sheet TRABALHO REAL
B2: Nível da estrutura de tópicos | C2: Status | D2: Crítica | E2: Nome da Tarefa | F2: % LB Prevista | G2: % Real | H2: Duração real | I2: Duração restante | J2: Início LB | K2: Início Real | L2: Previsão de Início | M2: Término LB | N2: Término Real | O2: Previsão de Término | P2: Custo | Q2: ='TRABALHO TENDÊNCIA'!Q2 -> 46160 | R2: ='TRABALHO TENDÊNCIA'!R2 -> 46167 | S2: ='TRABALHO TENDÊNCIA'!S2 -> 46174 | T2: ='TRABALHO TENDÊNCIA'!T2 -> 46181 | U2: ='TRABALHO TENDÊNCIA'!U2 -> 46188 | V2: ='TRABALHO TENDÊNCIA'!V2 -> 46195 | W2: ='TRABALHO TENDÊNCIA'!W2 -> 46202 | X2: ='TRABALHO TENDÊNCIA'!X2 -> 46209 | ... AR2: ='TRABALHO TENDÊNCIA'!AR2 -> 46349
B3: 0 | C3: No Prazo | D3: Sim | E3: UNIPAR_PROJETO_SPCI+PLATAFORMA | F3: 0.3414 | G3: 0.0824 | H3: 58,91 dias | I3: 59,09 dias | J3: Qua 20/05/26 09:00 | K3: Qua 20/05/26 09:00 | L3: Qua 20/05/26 09:00 | M3: Qua 21/10/26 16:00 | N3: ND | O3: Qui 05/11/26 16:00 | P3: 10028.87 | T3: 185.46 | U3: 214.62 | V3: 243.77 | W3: 272.93 | X3: 342.09 | Y3: 386.94 | Z3: 713.31 | AA3: 713.31 | AB3: 778.31 | AC3: 778.31 | AD3: 778.31 | AE3: 778.31 | AF3: 778.31 | AG3: 778.31 | AH3: 778.31 | AI3: 778.31 | AJ3: 778.31 | AK3: 778.31 | AL3: 778.31 | AM3: 778.31 | AN3: 778.31 | AO3: 778.31
B4: 1 | C4: Atrasada | D4: Não | E4: MARCOS CONTRATUAIS | F4: 0 | G4: 0 | H4: 0 dias | I4: 103,14 dias | J4: Qua 20/05/26 09:00 | K4: Qua 20/05/26 09:00 | L4: Qua 20/05/26 09:00 | M4: Qua 30/09/26 09:52 | N4: ND | O4: Qui 15/10/26 09:52 | P4: 0
B5: 2 | C5: Atrasada | D5: Não | E5: MARCOS CONTRATUAIS | F5: 0 | G5: 0 | H5: 0 dias | I5: 103,14 dias | J5: ND | K5: Qua 20/05/26 09:00 | L5: Qua 20/05/26 09:00 | M5: ND | N5: ND | O5: Qui 15/10/26 09:52 | P5: 0
B6: 3 | C6: Atrasada | D6: Não | E6: MARCOS CONTRATUAIS | F6: 0 | G6: 0 | H6: 0 dias | I6: 103,14 dias | J6: ND | K6: Qua 20/05/26 09:00 | L6: Qua 20/05/26 09:00 | M6: ND | N6: ND | O6: Qui 15/10/26 09:52 | P6: 0
B7: 4 | C7: Atrasada | D7: Não | E7: MARCOS CONTRATUAIS | F7: 0 | G7: 0 | H7: 0 dias | I7: 103,14 dias | J7: ND | K7: Qua 20/05/26 09:00 | L7: Qua 20/05/26 09:00 | M7: ND | N7: ND | O7: Qui 15/10/26 09:52 | P7: 0
B8: 1 | C8: No Prazo | D8: Não | E8: EXECUÇÃO - SPCI | F8: 0.4879 | G8: 0.1618 | H8: 54,51 dias | I8: 36,63 dias | J8: Seg 08/06/26 09:00 | K8: Seg 08/06/26 09:00 | L8: Seg 08/06/26 09:00 | M8: Qua 30/09/26 09:52 | N8: ND | O8: Qui 15/10/26 09:52 | P8: 5107.87 | T8: 185.46 | U8: 214.62 | V8: 243.77 | W8: 272.93 | X8: 342.09 | Y8: 386.94 | Z8: 713.31 | AA8: 713.31 | AB8: 778.31 | AC8: 778.31 | AD8: 778.31 | AE8: 778.31 | AF8: 778.31 | AG8: 778.31 | AH8: 778.31 | AI8: 778.31 | AJ8: 778.31 | AK8: 778.31 | AL8: 778.31 | AM8: 778.31 | AN8: 778.31 | AO8: 778.31
B9: 2 | C9: No Prazo | D9: Não | E9: CWA (ÁREA 2 - SETOR X) | F9: 0.7234 | G9: 0.2216 | H9: 58,48 dias | I9: 22,82 dias | J9: Seg 08/06/26 09:00 | K9: Seg 08/06/26 09:00 | L9: Seg 08/06/26 09:00 | M9: Qua 16/09/26 10:46 | N9: ND | O9: Qua 30/09/26 10:46 | P9: 2695.9 | T9: 185.46 | U9: 196.72 | V9: 207.97 | W9: 219.23 | X9: 270.49 | Y9: 279.34 | Z9: 597.31 | AA9: 597.31 | AB9: 597.31 | AC9: 597.31 | AD9: 597.31 | AE9: 597.31 | AF9: 597.31 | AG9: 597.31 | AH9: 597.31 | AI9: 597.31 | AJ9: 597.31 | AK9: 597.31 | AL9: 597.31 | AM9: 597.31 | AN9: 597.31 | AO9: 597.31
B10: 3 | C10: No Prazo | D10: Não | E10: CWP (ANDAIME) | F10: 0 | G10: 0 | H10: 0 dias | I10: 0 dias | J10: Sáb 25/07/26 16:00 | K10: ND | L10: Sex 07/08/26 16:00 | M10: Sáb 25/07/26 16:00 | N10: ND | O10: Sex 07/08/26 16:00 | P10: 0
B11: 4 | C11: No Prazo | D11: Não | E11: IWP (MONTAGEM) | F11: 0 | G11: 0 | H11: 0 dias | I11: 0 dias | J11: Sáb 25/07/26 16:00 | K11: ND | L11: Sex 07/08/26 16:00 | M11: Sáb 25/07/26 16:00 | N11: ND | O11: Sex 07/08/26 16:00 | P11: 0
B12: 3 | C12: No Prazo | D12: Não | E12: CWP (TUBULAÇÃO) | F12: 0.7153 | G12: 0.2556 | H12: 61,53 dias | I12: 18,1 dias | J12: Seg 08/06/26 09:00 | K12: Seg 08/06/26 09:00 | L12: Seg 08/06/26 09:00 | M12: Seg 14/09/26 13:46 | N12: ND | O12: Seg 28/09/26 13:46 | P12: 2337.3 | T12: 185.46 | U12: 196.72 | V12: 207.97 | W12: 219.23 | X12: 270.49 | Y12: 279.34 | Z12: 597.31 | AA12: 597.31 | AB12: 597.31 | AC12: 597.31 | AD12: 597.31 | AE12: 597.31 | AF12: 597.31 | AG12: 597.31 | AH12: 597.31 | AI12: 597.31 | AJ12: 597.31 | AK12: 597.31 | AL12: 597.31 | AM12: 597.31 | AN12: 597.31 | AO12: 597.31
B13: 4 | C13: Concluída | D13: Não | E13: IWP (FABRICAÇÃO) | F13: 1 | G13: 1 | H13: 35 dias | I13: 0 dias | J13: Seg 08/06/26 09:00 | K13: Seg 08/06/26 09:00 | L13: Seg 08/06/26 09:00 | M13: Qua 29/07/26 11:00 | N13: Sáb 25/07/26 15:36 | O13: Sáb 25/07/26 15:36 | P13: 391.2 | T13: 185.46 | U13: 196.72 | V13: 207.97 | W13: 219.23 | X13: 230.49 | Y13: 239.34 | Z13: 391.2 | AA13: 391.2 | AB13: 391.2 | AC13: 391.2 | AD13: 391.2 | AE13: 391.2 | AF13: 391.2 | AG13: 391.2 | AH13: 391.2 | AI13: 391.2 | AJ13: 391.2 | AK13: 391.2 | AL13: 391.2 | AM13: 391.2 | AN13: 391.2 | AO13: 391.2
B14: 4 | C14: Concluída | D14: Não | E14: IWP (SUPORTE - FABRICAÇÃO) | F14: 1 | G14: 1 | H14: 10 dias | I14: 0 dias | J14: Seg 29/06/26 09:00 | K14: Seg 29/06/26 09:00 | L14: Seg 29/06/26 09:00 | M14: Sex 10/07/26 16:00 | N14: Sex 10/07/26 16:00 | O14: Sex 10/07/26 16:00 | P14: 40 | W14: 0 | X14: 40 | Y14: 40 | Z14: 40 | AA14: 40 | AB14: 40 | AC14: 40 | AD14: 40 | AE14: 40 | AF14: 40 | AG14: 40 | AH14: 40 | AI14: 40 | AJ14: 40 | AK14: 40 | AL14: 40 | AM14: 40 | AN14: 40 | AO14: 40
B15: 4 | C15: Tarefa futura | D15: Não | E15: IWP (SUPORTE - MONTAGEM) | F15: 1 | G15: 0 | H15: 0 dias | I15: 7,92 dias | J15: Seg 27/07/26 09:00 | K15: ND | L15: Seg 10/08/26 09:00 | M15: Qua 05/08/26 15:30 | N15: ND | O15: Qua 19/08/26 15:30 | P15: 95
B16: 4 | C16: No Prazo | D16: Não | E16: IWP (MONTAGEM) | F16: 0.6525 | G16: 0.0954 | H16: 4,5 dias | I16: 38,77 dias | J16: Seg 20/07/26 09:00 | K16: Seg 20/07/26 09:00 | L16: Seg 20/07/26 09:00 | M16: Qui 03/09/26 10:37 | N16: ND | O16: Sex 18/09/26 10:37 | P16: 1742.1 | Z16: 166.11 | AA16: 166.11 | AB16: 166.11 | AC16: 166.11 | AD16: 166.11 | AE16: 166.11 | AF16: 166.11 | AG16: 166.11 | AH16: 166.11 | AI16: 166.11 | AJ16: 166.11 | AK16: 166.11 | AL16: 166.11 | AM16: 166.11 | AN16: 166.11 | AO16: 166.11
B17: 4 | C17: Tarefa futura | D17: Não | E17: IWP (CIVIL) | F17: 1 | G17: 0 | H17: 0 dias | I17: 1,5 dias | J17: Seg 03/08/26 15:00 | K17: ND | L17: Seg 10/08/26 09:00 | M17: Qua 05/08/26 11:00 | N17: ND | O17: Ter 11/08/26 12:00 | P17: 9
B18: 4 | C18: Tarefa futura | D18: Não | E18: IWP (TIE-IN) | F18: 0 | G18: 0 | H18: 0 dias | I18: 1,67 dias | J18: Qui 10/09/26 15:46 | K18: ND | L18: Qui 24/09/26 15:46 | M18: Seg 14/09/26 13:46 | N18: ND | O18: Seg 28/09/26 13:46 | P18: 60
B19: 3 | C19: Tarefa futura | D19: Não | E19: CWP (ELÉTRICA) | F19: 0.8216 | G19: 0 | H19: 0 dias | I19: 12,62 dias | J19: Seg 27/07/26 09:00 | K19: ND | L19: Seg 10/08/26 09:00 | M19: Qua 12/08/26 13:42 | N19: ND | O19: Qua 26/08/26 13:42 | P19: 338.6
B20: 4 | C20: Tarefa futura | D20: Não | E20: IWP (INFRAESTRUTURA) FABRICAR DE SUPORTE | F20: 1 | G20: 0 | H20: 0 dias | I20: 1,67 dias | J20: Seg 27/07/26 09:00 | K20: ND | L20: Seg 10/08/26 09:00 | M20: Ter 28/07/26 14:00 | N20: ND | O20: Ter 11/08/26 14:00 | P20: 20
B21: 4 | C21: Tarefa futura | D21: Não | E21: IWP (INFRAESTRUTURA) MONTAGEM DE SUPORTE | F21: 1 | G21: 0 | H21: 0 dias | I21: 1,67 dias | J21: Ter 28/07/26 14:00 | K21: ND | L21: Ter 11/08/26 14:00 | M21: Qui 30/07/26 11:00 | N21: ND | O21: Qui 13/08/26 11:00 | P21: 20
B22: 4 | C22: Tarefa futura | D22: Não | E22: IWP (INFRAESTRUTURA) MONTAGEM DE ELETROCALHA | F22: 1 | G22: 0 | H22: 0 dias | I22: 7,95 dias | J22: Qua 29/07/26 09:00 | K22: ND | L22: Qua 12/08/26 09:00 | M22: Sex 07/08/26 15:42 | N22: ND | O22: Sex 21/08/26 15:42 | P22: 201.6
B23: 4 | C23: Tarefa futura | D23: Não | E23: IWP (CABEAMENTO) | F23: 0.4486 | G23: 0 | H23: 0 dias | I23: 5,68 dias | J23: Seg 03/08/26 13:36 | K23: ND | L23: Seg 17/08/26 13:36 | M23: Ter 11/08/26 10:42 | N23: ND | O23: Ter 25/08/26 10:42 | P23: 37
B24: 4 | C24: Tarefa futura | D24: Não | E24: IWP (INSTALAÇÃO DE MALHA) | F24: 0.3333 | G24: 0 | H24: 0 dias | I24: 10,62 dias | J24: Qua 29/07/26 09:00 | K24: ND | L24: Qua 12/08/26 09:00 | M24: Qua 12/08/26 13:42 | N24: ND | O24: Qua 26/08/26 13:42 | P24: 48
B25: 4 | C25: Tarefa futura | D25: Não | E25: IWP (TESTE) | F25: 0.3333 | G25: 0 | H25: 0 dias | I25: 5,18 dias | J25: Ter 04/08/26 10:36 | K25: ND | L25: Ter 18/08/26 10:36 | M25: Ter 11/08/26 11:42 | N25: ND | O25: Ter 25/08/26 11:42 | P25: 6
B26: 4 | C26: Tarefa futura | D26: Não | E26: IWP (LIGAÇÃO) | F26: 0.3333 | G26: 0 | H26: 0 dias | I26: 6,18 dias | J26: Ter 04/08/26 11:36 | K26: ND | L26: Ter 18/08/26 11:36 | M26: Qua 12/08/26 13:42 | N26: ND | O26: Qua 26/08/26 13:42 | P26: 6
B27: 3 | C27: Tarefa futura | D27: Não | E27: CWP (TESTE HIDROSTÁTICO) | F27: 0 | G27: 0 | H27: 0 dias | I27: 1,67 dias | J27: Seg 14/09/26 13:46 | K27: ND | L27: Seg 28/09/26 13:46 | M27: Qua 16/09/26 10:46 | N27: ND | O27: Qua 30/09/26 10:46 | P27: 20
B28: 4 | C28: Tarefa futura | D28: Não | E28: IWP (TESDE HIDROSTÁTICO) | F28: 0 | G28: 0 | H28: 0 dias | I28: 1,67 dias | J28: Seg 14/09/26 13:46 | K28: ND | L28: Seg 28/09/26 13:46 | M28: Qua 16/09/26 10:46 | N28: ND | O28: Qua 30/09/26 10:46 | P28: 20
... B31: 3 | C31: Tarefa futura | D31: Não | E31: CONCLUSÃO DA EXECUÇÃO DA ÁREA | F31: 0 | G31: 0 | H31: 0 dias | I31: 0 dias | J31: Qua 16/09/26 10:46 | K31: ND | L31: Qua 30/09/26 10:46 | M31: Qua 16/09/26 10:46 | N31: ND | O31: Qua 30/09/26 10:46 | P31: 0
B32: 2 | C32: No Prazo | D32: Não | E32: CWA (ÁREA 3 - SETOR P/T) | F32: 0.3118 | G32: 0.1896 | H32: 48,27 dias | I32: 29,69 dias | J32: Seg 15/06/26 09:00 | K32: Seg 15/06/26 09:00 | L32: Seg 15/06/26 09:00 | M32: Qui 17/09/26 15:46 | N32: ND | O32: Qui 01/10/26 15:46 | P32: 838.6 | U32: 10.4 | V32: 20.8 | W32: 31.2 | X32: 41.6 | Y32: 77.6 | Z32: 86 | AA32: 86 | AB32: 111 | AC32: 111 | AD32: 111 | AE32: 111 | AF32: 111 | AG32: 111 | AH32: 111 | AI32: 111 | AJ32: 111 | AK32: 111 | AL32: 111 | AM32: 111 | AN32: 111 | AO32: 111
B33: 3 | C33: Tarefa futura | D33: Não | E33: CWP (ANDAIME) | F33: 0 | G33: 0 | H33: 0 dias | I33: 0 dias | J33: Qui 03/09/26 10:37 | K33: ND | L33: Sex 18/09/26 10:37 | M33: Qui 03/09/26 10:37 | N33: ND | O33: Sex 18/09/26 10:37 | P33: 0
B34: 4 | C34: Tarefa futura | D34: Não | E34: IWP (MONTAGEM) | F34: 0 | G34: 0 | H34: 0 dias | I34: 0 dias | J34: Qui 03/09/26 10:37 | K34: ND | L34: Sex 18/09/26 10:37 | M34: Qui 03/09/26 10:37 | N34: ND | O34: Sex 18/09/26 10:37 | P34: 0
B35: 3 | C35: No Prazo | D35: Não | E35: CWP (TUBULAÇÃO) | F35: 0.3512 | G35: 0.2135 | H35: 50,17 dias | I35: 26,13 dias | J35: Seg 15/06/26 09:00 | K35: Seg 15/06/26 09:00 | L35: Seg 15/06/26 09:00 | M35: Qua 16/09/26 10:46 | N35: ND | O35: Qua 30/09/26 10:46 | P35: 744.6 | U35: 10.4 | V35: 20.8 | W35: 31.2 | X35: 41.6 | Y35: 77.6 | Z35: 86 | AA35: 86 | AB35: 111 | AC35: 111 | AD35: 111 | AE35: 111 | AF35: 111 | AG35: 111 | AH35: 111 | AI35: 111 | AJ35: 111 | AK35: 111 | AL35: 111 | AM35: 111 | AN35: 111 | AO35: 111
B36: 4 | C36: No Prazo | D36: Não | E36: IWP (FABRICAÇÃO) | F36: 1 | G36: 0.6761 | H36: 39,1 dias | I36: 3,4 dias | J36: Seg 15/06/26 09:00 | K36: Seg 15/06/26 09:00 | L36: Seg 15/06/26 09:00 | M36: Qua 29/07/26 12:00 | N36: ND | O36: Qua 12/08/26 12:00 | P36: 127.2 | U36: 10.4 | V36: 20.8 | W36: 31.2 | X36: 41.6 | Y36: 77.6 | Z36: 86 | AA36: 86 | AB36: 86 | AC36: 86 | AD36: 86 | AE36: 86 | AF36: 86 | AG36: 86 | AH36: 86 | AI36: 86 | AJ36: 86 | AK36: 86 | AL36: 86 | AM36: 86 | AN36: 86 | AO36: 86
B37: 4 | C37: Concluída | D37: Não | E37: IWP (SUPORTE - FABRICAÇÃO) | F37: 1 | G37: 1 | H37: 4 dias | I37: 0 dias | J37: Seg 27/07/26 09:00 | K37: Ter 04/08/26 09:00 | L37: Ter 04/08/26 09:00 | M37: Sex 31/07/26 10:00 | N37: Sex 07/08/26 16:00 | O37: Sex 07/08/26 16:00 | P37: 25 | AB37: 25 | AC37: 25 | AD37: 25 | AE37: 25 | AF37: 25 | AG37: 25 | AH37: 25 | AI37: 25 | AJ37: 25 | AK37: 25 | AL37: 25 | AM37: 25 | AN37: 25 | AO37: 25
B38: 4 | C38: Tarefa futura | D38: Não | E38: IWP (SUPORTE - MONTAGEM) | F38: 0.5208 | G38: 1 | H38: 0 dias | I38: 4 dias | J38: Qua 05/08/26 15:30 | K38: ND | L38: Qua 19/08/26 15:30 | M38: Ter 11/08/26 15:30 | N38: ND | O38: Ter 25/08/26 15:30 | P38: 48
B39: 4 | C39: Tarefa futura | D39: Não | E39: IWP (MONTAGEM) | F39: 0.1571 | G39: 0 | H39: 0 dias | I39: 17,03 dias | J39: Ter 04/08/26 09:48 | K39: ND | L39: Ter 18/08/26 09:48 | M39: Qui 27/08/26 10:00 | N39: ND | O39: Sex 11/09/26 10:00 | P39: 498.4
B40: 4 | C40: Tarefa futura | D40: Não | E40: IWP (CIVIL) | F40: 1 | G40: 0 | H40: 0 dias | I40: 1 dia | J40: Qua 05/08/26 11:00 | K40: ND | L40: Ter 11/08/26 13:00 | M40: Qui 06/08/26 11:00 | N40: ND | O40: Qua 12/08/26 12:00 | P40: 6
B41: 4 | C41: Tarefa futura | D41: Não | E41: IWP (TIE-IN) | F41: 0 | G41: 0 | H41: 0 dias | I41: 1,67 dias | J41: Seg 14/09/26 13:46 | K41: ND | L41: Seg 28/09/26 13:46 | M41: Qua 16/09/26 10:46 | N41: ND | O41: Qua 30/09/26 10:46 | P41: 40
B42: 3 | C42: Tarefa futura | D42: Não | E42: CWP (ELÉTRICA) | F42: 0 | G42: 0 | H42: 0 dias | I42: 6 dias | J42: Qua 12/08/26 13:42 | K42: ND | L42: Qua 26/08/26 13:42 | M42: Qui 20/08/26 13:42 | N42: ND | O42: Qui 03/09/26 13:42 | P42: 74
B43: 4 | C43: Tarefa futura | D43: Não | E43: IWP (CABEAMENTO) | F43: 0 | G43: 0 | H43: 0 dias | I43: 2,83 dias | J43: Qua 12/08/26 13:42 | K43: ND | L43: Qua 26/08/26 13:42 | M43: Seg 17/08/26 11:42 | N43: ND | O43: Seg 31/08/26 11:42 | P43: 34
...
